[2024-08-01T15:10:31.778-0300] {local_task_job_runner.py:120} INFO - ::group::Pre task execution logs
[2024-08-01T15:10:31.790-0300] {taskinstance.py:2076} INFO - Dependencies all met for dep_context=non-requeueable deps ti=<TaskInstance: weather_dag.get_weather manual__2024-08-01T18:07:23.856022+00:00 [queued]>
[2024-08-01T15:10:31.793-0300] {taskinstance.py:2076} INFO - Dependencies all met for dep_context=requeueable deps ti=<TaskInstance: weather_dag.get_weather manual__2024-08-01T18:07:23.856022+00:00 [queued]>
[2024-08-01T15:10:31.793-0300] {taskinstance.py:2306} INFO - Starting attempt 4 of 6
[2024-08-01T15:10:31.801-0300] {taskinstance.py:2330} INFO - Executing <Task(BashOperator): get_weather> on 2024-08-01 18:07:23.856022+00:00
[2024-08-01T15:10:31.804-0300] {standard_task_runner.py:64} INFO - Started process 90213 to run task
[2024-08-01T15:10:31.806-0300] {standard_task_runner.py:90} INFO - Running: ['airflow', 'tasks', 'run', 'weather_dag', 'get_weather', 'manual__2024-08-01T18:07:23.856022+00:00', '--job-id', '551', '--raw', '--subdir', 'DAGS_FOLDER/weather_dag.py', '--cfg-path', '/tmp/tmplm7ao7n5']
[2024-08-01T15:10:31.806-0300] {standard_task_runner.py:91} INFO - Job 551: Subtask get_weather
[2024-08-01T15:10:31.829-0300] {task_command.py:426} INFO - Running <TaskInstance: weather_dag.get_weather manual__2024-08-01T18:07:23.856022+00:00 [running]> on host BOOK-U1A3RU270O.
[2024-08-01T15:10:31.864-0300] {taskinstance.py:2648} INFO - Exporting env vars: AIRFLOW_CTX_DAG_EMAIL='marceloc.bastos@hotmail.com' AIRFLOW_CTX_DAG_OWNER='Marcelo' AIRFLOW_CTX_DAG_ID='weather_dag' AIRFLOW_CTX_TASK_ID='get_weather' AIRFLOW_CTX_EXECUTION_DATE='2024-08-01T18:07:23.856022+00:00' AIRFLOW_CTX_TRY_NUMBER='4' AIRFLOW_CTX_DAG_RUN_ID='manual__2024-08-01T18:07:23.856022+00:00'
[2024-08-01T15:10:31.865-0300] {taskinstance.py:430} INFO - ::endgroup::
[2024-08-01T15:10:31.866-0300] {subprocess.py:63} INFO - Tmp dir root location: /tmp
[2024-08-01T15:10:31.866-0300] {subprocess.py:75} INFO - Running command: ['/usr/bin/bash', '-c', 'python /home/mcb/code/marcelo7bastos/airflow/dags/src/get_weather.py']
[2024-08-01T15:10:31.871-0300] {subprocess.py:86} INFO - Output:
[2024-08-01T15:10:31.878-0300] {subprocess.py:93} INFO - python: can't open file '/home/mcb/code/marcelo7bastos/airflow/dags/src/get_weather.py': [Errno 2] No such file or directory
[2024-08-01T15:10:31.880-0300] {subprocess.py:97} INFO - Command exited with return code 2
[2024-08-01T15:10:31.881-0300] {taskinstance.py:441} INFO - ::group::Post task execution logs
[2024-08-01T15:10:31.884-0300] {taskinstance.py:2905} ERROR - Task failed with exception
Traceback (most recent call last):
  File "/home/mcb/.pyenv/versions/venv_airflow_mda/lib/python3.12/site-packages/airflow/models/taskinstance.py", line 465, in _execute_task
    result = _execute_callable(context=context, **execute_callable_kwargs)
             ^^^^^^^^^^^^^^^^^^^^^^^^^^^^^^^^^^^^^^^^^^^^^^^^^^^^^^^^^^^^^
  File "/home/mcb/.pyenv/versions/venv_airflow_mda/lib/python3.12/site-packages/airflow/models/taskinstance.py", line 432, in _execute_callable
    return execute_callable(context=context, **execute_callable_kwargs)
           ^^^^^^^^^^^^^^^^^^^^^^^^^^^^^^^^^^^^^^^^^^^^^^^^^^^^^^^^^^^^
  File "/home/mcb/.pyenv/versions/venv_airflow_mda/lib/python3.12/site-packages/airflow/models/baseoperator.py", line 401, in wrapper
    return func(self, *args, **kwargs)
           ^^^^^^^^^^^^^^^^^^^^^^^^^^^
  File "/home/mcb/.pyenv/versions/venv_airflow_mda/lib/python3.12/site-packages/airflow/operators/bash.py", line 243, in execute
    raise AirflowException(
airflow.exceptions.AirflowException: Bash command failed. The command returned a non-zero exit code 2.
[2024-08-01T15:10:31.886-0300] {taskinstance.py:1206} INFO - Marking task as UP_FOR_RETRY. dag_id=weather_dag, task_id=get_weather, run_id=manual__2024-08-01T18:07:23.856022+00:00, execution_date=20240801T180723, start_date=20240801T181031, end_date=20240801T181031
[2024-08-01T15:10:31.894-0300] {standard_task_runner.py:110} ERROR - Failed to execute job 551 for task get_weather (Bash command failed. The command returned a non-zero exit code 2.; 90213)
[2024-08-01T15:10:31.899-0300] {local_task_job_runner.py:243} INFO - Task exited with return code 1
[2024-08-01T15:10:31.908-0300] {taskinstance.py:3503} INFO - 0 downstream tasks scheduled from follow-on schedule check
[2024-08-01T15:10:31.908-0300] {local_task_job_runner.py:222} INFO - ::endgroup::
