[2024-08-01T14:42:33.828-0300] {local_task_job_runner.py:120} INFO - ::group::Pre task execution logs
[2024-08-01T14:42:33.841-0300] {taskinstance.py:2076} INFO - Dependencies all met for dep_context=non-requeueable deps ti=<TaskInstance: weather_dag.get_weather scheduled__2024-07-31T03:00:00+00:00 [queued]>
[2024-08-01T14:42:33.844-0300] {taskinstance.py:2076} INFO - Dependencies all met for dep_context=requeueable deps ti=<TaskInstance: weather_dag.get_weather scheduled__2024-07-31T03:00:00+00:00 [queued]>
[2024-08-01T14:42:33.844-0300] {taskinstance.py:2306} INFO - Starting attempt 1 of 6
[2024-08-01T14:42:33.853-0300] {taskinstance.py:2330} INFO - Executing <Task(BashOperator): get_weather> on 2024-07-31 03:00:00+00:00
[2024-08-01T14:42:33.856-0300] {standard_task_runner.py:64} INFO - Started process 71291 to run task
[2024-08-01T14:42:33.858-0300] {standard_task_runner.py:90} INFO - Running: ['airflow', 'tasks', 'run', 'weather_dag', 'get_weather', 'scheduled__2024-07-31T03:00:00+00:00', '--job-id', '294', '--raw', '--subdir', 'DAGS_FOLDER/weather_dag.py', '--cfg-path', '/tmp/tmpeh565k1s']
[2024-08-01T14:42:33.858-0300] {standard_task_runner.py:91} INFO - Job 294: Subtask get_weather
[2024-08-01T14:42:33.881-0300] {task_command.py:426} INFO - Running <TaskInstance: weather_dag.get_weather scheduled__2024-07-31T03:00:00+00:00 [running]> on host BOOK-U1A3RU270O.
[2024-08-01T14:42:33.921-0300] {taskinstance.py:2648} INFO - Exporting env vars: AIRFLOW_CTX_DAG_EMAIL='marceloc.bastos@hotmail.com' AIRFLOW_CTX_DAG_OWNER='Marcelo' AIRFLOW_CTX_DAG_ID='weather_dag' AIRFLOW_CTX_TASK_ID='get_weather' AIRFLOW_CTX_EXECUTION_DATE='2024-07-31T03:00:00+00:00' AIRFLOW_CTX_TRY_NUMBER='1' AIRFLOW_CTX_DAG_RUN_ID='scheduled__2024-07-31T03:00:00+00:00'
[2024-08-01T14:42:33.922-0300] {taskinstance.py:430} INFO - ::endgroup::
[2024-08-01T14:42:33.922-0300] {subprocess.py:63} INFO - Tmp dir root location: /tmp
[2024-08-01T14:42:33.922-0300] {subprocess.py:75} INFO - Running command: ['/usr/bin/bash', '-c', 'python /home/mcb/code/marcelo7bastos/airflow/dags/src/get_weather.py']
[2024-08-01T14:42:33.927-0300] {subprocess.py:86} INFO - Output:
[2024-08-01T14:42:33.934-0300] {subprocess.py:93} INFO - python: can't open file '/home/mcb/code/marcelo7bastos/airflow/dags/src/get_weather.py': [Errno 2] No such file or directory
[2024-08-01T14:42:33.936-0300] {subprocess.py:97} INFO - Command exited with return code 2
[2024-08-01T14:42:33.936-0300] {taskinstance.py:441} INFO - ::group::Post task execution logs
[2024-08-01T14:42:33.940-0300] {taskinstance.py:2905} ERROR - Task failed with exception
Traceback (most recent call last):
  File "/home/mcb/.pyenv/versions/venv_airflow_mda/lib/python3.12/site-packages/airflow/models/taskinstance.py", line 465, in _execute_task
    result = _execute_callable(context=context, **execute_callable_kwargs)
             ^^^^^^^^^^^^^^^^^^^^^^^^^^^^^^^^^^^^^^^^^^^^^^^^^^^^^^^^^^^^^
  File "/home/mcb/.pyenv/versions/venv_airflow_mda/lib/python3.12/site-packages/airflow/models/taskinstance.py", line 432, in _execute_callable
    return execute_callable(context=context, **execute_callable_kwargs)
           ^^^^^^^^^^^^^^^^^^^^^^^^^^^^^^^^^^^^^^^^^^^^^^^^^^^^^^^^^^^^
  File "/home/mcb/.pyenv/versions/venv_airflow_mda/lib/python3.12/site-packages/airflow/models/baseoperator.py", line 401, in wrapper
    return func(self, *args, **kwargs)
           ^^^^^^^^^^^^^^^^^^^^^^^^^^^
  File "/home/mcb/.pyenv/versions/venv_airflow_mda/lib/python3.12/site-packages/airflow/operators/bash.py", line 243, in execute
    raise AirflowException(
airflow.exceptions.AirflowException: Bash command failed. The command returned a non-zero exit code 2.
[2024-08-01T14:42:33.942-0300] {taskinstance.py:1206} INFO - Marking task as UP_FOR_RETRY. dag_id=weather_dag, task_id=get_weather, run_id=scheduled__2024-07-31T03:00:00+00:00, execution_date=20240731T030000, start_date=20240801T174233, end_date=20240801T174233
[2024-08-01T14:42:33.949-0300] {standard_task_runner.py:110} ERROR - Failed to execute job 294 for task get_weather (Bash command failed. The command returned a non-zero exit code 2.; 71291)
[2024-08-01T14:42:33.991-0300] {local_task_job_runner.py:243} INFO - Task exited with return code 1
[2024-08-01T14:42:34.001-0300] {taskinstance.py:3503} INFO - 0 downstream tasks scheduled from follow-on schedule check
[2024-08-01T14:42:34.001-0300] {local_task_job_runner.py:222} INFO - ::endgroup::
