[2024-08-01T16:12:12.424-0300] {local_task_job_runner.py:120} INFO - ::group::Pre task execution logs
[2024-08-01T16:12:12.438-0300] {taskinstance.py:2076} INFO - Dependencies all met for dep_context=non-requeueable deps ti=<TaskInstance: new_dag_test_macelo.get_weather scheduled__2024-07-29T01:00:00+00:00 [queued]>
[2024-08-01T16:12:12.441-0300] {taskinstance.py:2076} INFO - Dependencies all met for dep_context=requeueable deps ti=<TaskInstance: new_dag_test_macelo.get_weather scheduled__2024-07-29T01:00:00+00:00 [queued]>
[2024-08-01T16:12:12.441-0300] {taskinstance.py:2306} INFO - Starting attempt 5 of 6
[2024-08-01T16:12:12.450-0300] {taskinstance.py:2330} INFO - Executing <Task(BashOperator): get_weather> on 2024-07-29 01:00:00+00:00
[2024-08-01T16:12:12.453-0300] {standard_task_runner.py:64} INFO - Started process 116799 to run task
[2024-08-01T16:12:12.455-0300] {standard_task_runner.py:90} INFO - Running: ['airflow', 'tasks', 'run', 'new_dag_test_macelo', 'get_weather', 'scheduled__2024-07-29T01:00:00+00:00', '--job-id', '626', '--raw', '--subdir', 'DAGS_FOLDER/new_dag_test_macelo.py', '--cfg-path', '/tmp/tmprg9a4pnd']
[2024-08-01T16:12:12.456-0300] {standard_task_runner.py:91} INFO - Job 626: Subtask get_weather
[2024-08-01T16:12:12.479-0300] {task_command.py:426} INFO - Running <TaskInstance: new_dag_test_macelo.get_weather scheduled__2024-07-29T01:00:00+00:00 [running]> on host BOOK-U1A3RU270O.
[2024-08-01T16:12:12.513-0300] {taskinstance.py:2648} INFO - Exporting env vars: AIRFLOW_CTX_DAG_EMAIL='marceloc.bastos@hotmail.com' AIRFLOW_CTX_DAG_OWNER='Marcelo' AIRFLOW_CTX_DAG_ID='new_dag_test_macelo' AIRFLOW_CTX_TASK_ID='get_weather' AIRFLOW_CTX_EXECUTION_DATE='2024-07-29T01:00:00+00:00' AIRFLOW_CTX_TRY_NUMBER='5' AIRFLOW_CTX_DAG_RUN_ID='scheduled__2024-07-29T01:00:00+00:00'
[2024-08-01T16:12:12.514-0300] {taskinstance.py:430} INFO - ::endgroup::
[2024-08-01T16:12:12.515-0300] {subprocess.py:63} INFO - Tmp dir root location: /tmp
[2024-08-01T16:12:12.515-0300] {subprocess.py:75} INFO - Running command: ['/usr/bin/bash', '-c', 'python /home/mcb/code/marcelo7bastos/airflow/dags/src/get_weather.py']
[2024-08-01T16:12:12.521-0300] {subprocess.py:86} INFO - Output:
[2024-08-01T16:12:12.529-0300] {subprocess.py:93} INFO - python: can't open file '/home/mcb/code/marcelo7bastos/airflow/dags/src/get_weather.py': [Errno 2] No such file or directory
[2024-08-01T16:12:12.531-0300] {subprocess.py:97} INFO - Command exited with return code 2
[2024-08-01T16:12:12.531-0300] {taskinstance.py:441} INFO - ::group::Post task execution logs
[2024-08-01T16:12:12.536-0300] {taskinstance.py:2905} ERROR - Task failed with exception
Traceback (most recent call last):
  File "/home/mcb/.pyenv/versions/venv_airflow_mda/lib/python3.12/site-packages/airflow/models/taskinstance.py", line 465, in _execute_task
    result = _execute_callable(context=context, **execute_callable_kwargs)
             ^^^^^^^^^^^^^^^^^^^^^^^^^^^^^^^^^^^^^^^^^^^^^^^^^^^^^^^^^^^^^
  File "/home/mcb/.pyenv/versions/venv_airflow_mda/lib/python3.12/site-packages/airflow/models/taskinstance.py", line 432, in _execute_callable
    return execute_callable(context=context, **execute_callable_kwargs)
           ^^^^^^^^^^^^^^^^^^^^^^^^^^^^^^^^^^^^^^^^^^^^^^^^^^^^^^^^^^^^
  File "/home/mcb/.pyenv/versions/venv_airflow_mda/lib/python3.12/site-packages/airflow/models/baseoperator.py", line 401, in wrapper
    return func(self, *args, **kwargs)
           ^^^^^^^^^^^^^^^^^^^^^^^^^^^
  File "/home/mcb/.pyenv/versions/venv_airflow_mda/lib/python3.12/site-packages/airflow/operators/bash.py", line 243, in execute
    raise AirflowException(
airflow.exceptions.AirflowException: Bash command failed. The command returned a non-zero exit code 2.
[2024-08-01T16:12:12.539-0300] {taskinstance.py:1206} INFO - Marking task as UP_FOR_RETRY. dag_id=new_dag_test_macelo, task_id=get_weather, run_id=scheduled__2024-07-29T01:00:00+00:00, execution_date=20240729T010000, start_date=20240801T191212, end_date=20240801T191212
[2024-08-01T16:12:12.546-0300] {standard_task_runner.py:110} ERROR - Failed to execute job 626 for task get_weather (Bash command failed. The command returned a non-zero exit code 2.; 116799)
[2024-08-01T16:12:12.588-0300] {local_task_job_runner.py:243} INFO - Task exited with return code 1
[2024-08-01T16:12:12.599-0300] {taskinstance.py:3503} INFO - 0 downstream tasks scheduled from follow-on schedule check
[2024-08-01T16:12:12.600-0300] {local_task_job_runner.py:222} INFO - ::endgroup::
